Workbook

Sheet Data and Analysis
A1: ROOFING SHINGLES DATASET
A3: Bundles | L3: Bundles
A4: Attributes / Bundles | B4: Bundle 1 | C4: Bundle 2 | D4: Bundle 3 | E4: Bundle 4 | F4: Bundle 5 | G4: Bundle 6 | H4: Bundle 7 | I4: Bundle 8 | J4: Bundle 9 | L4: Attributes / Bundles | M4: Life Expectancy | N4: Speed of Installation | O4: Shingle Aesthetics | P4: Price
A5: Life Expectancy | B5: Low Resistance | C5: Low Resistance | D5: Low Resistance | E5: Medium Resistance | F5: Medium Resistance | G5: Medium Resistance | H5: High Resistance | I5: High Resistance | J5: High Resistance | L5: Bundle 1 | M5: Low Resistance | N5: 1 week | O5: No Imperfections | P5: 10
A6: Speed of Installation | B6: 1 week | C6: 1.2 weeks | D6: 1.5 weeks | E6: 1 week | F6: 1.2 weeks | G6: 1.5 weeks | H6: 1 week | I6: 1.2 weeks | J6: 1.5 weeks | L6: Bundle 2 | M6: Low Resistance | N6: 1.2 weeks | O6: No Imperfections | P6: 9
A7: Shingle Aesthetics | B7: No Imperfections | C7: No Imperfections | D7: Minimal Imperfections | E7: Minimal Imperfections | F7: No Imperfections | G7: No Imperfections | H7: No Imperfections | I7: Minimal Imperfections | J7: No Imperfections | L7: Bundle 3 | M7: Low Resistance | N7: 1.5 weeks | O7: Minimal Imperfections | P7: 8
A8: Price | B8: 10 | C8: 9 | D8: 8 | E8: 9 | F8: 8 | G8: 10 | H8: 8 | I8: 10 | J8: 9 | L8: Bundle 4 | M8: Medium Resistance | N8: 1 week | O8: Minimal Imperfections | P8: 9
L9: Bundle 5 | M9: Medium Resistance | N9: 1.2 weeks | O9: No Imperfections | P9: 8
L10: Bundle 6 | M10: Medium Resistance | N10: 1.5 weeks | O10: No Imperfections | P10: 10
A11: Bundle Coding | L11: Bundle 7 | M11: High Resistance | N11: 1 week | O11: No Imperfections | P11: 8
A12: Bundle | B12: Dummy Variable | L12: Bundle 8 | M12: High Resistance | N12: 1.2 weeks | O12: Minimal Imperfections | P12: 10
B13: Resist_Med | C13: Resist_High | D13: Speed_1.2 | E13: Speed_1.5 | F13: Shingle_Minimal | G13: Price_9 | H13: Price_10 | L13: Bundle 9 | M13: High Resistance | N13: 1.5 weeks | O13: No Imperfections | P13: 9
A14: Bundle 1 | B14: {=_xlfn.IFS(M5="Low Resistance",0,M5="Medium Resistance",1,M5="High Resistance",0)} -> 0 | C14: {=_xlfn.IFS(M5="Low Resistance",0,M5="Medium Resistance",0,M5="High Resistance",1)} -> 0 | D14: {=_xlfn.IFS(N5="1 week",0,N5="1.2 weeks",1,N5="1.5 weeks",0)} -> 0 | E14: {=_xlfn.IFS(N5="1 week",0,N5="1.2 weeks",0,N5="1.5 weeks",1)} -> 0 | F14: {=_xlfn.IFS(O5="No Imperfections",0,O5="Minimal Imperfections",1)} -> 0 | G14: {=_xlfn.IFS(P5=8,0,P5=9,1,P5=10,0)} -> 0 | H14: {=_xlfn.IFS(P5=8,0,P5=9,0,P5=10,1)} -> 1
A15: Bundle 2 | B15: {=_xlfn.IFS(M6="Low Resistance",0,M6="Medium Resistance",1,M6="High Resistance",0)} -> 0 | C15: {=_xlfn.IFS(M6="Low Resistance",0,M6="Medium Resistance",0,M6="High Resistance",1)} -> 0 | D15: {=_xlfn.IFS(N6="1 week",0,N6="1.2 weeks",1,N6="1.5 weeks",0)} -> 1 | E15: {=_xlfn.IFS(N6="1 week",0,N6="1.2 weeks",0,N6="1.5 weeks",1)} -> 0 | F15: {=_xlfn.IFS(O6="No Imperfections",0,O6="Minimal Imperfections",1)} -> 0 | G15: {=_xlfn.IFS(P6=8,0,P6=9,1,P6=10,0)} -> 1 | H15: {=_xlfn.IFS(P6=8,0,P6=9,0,P6=10,1)} -> 0
A16: Bundle 3 | B16: {=_xlfn.IFS(M7="Low Resistance",0,M7="Medium Resistance",1,M7="High Resistance",0)} -> 0 | C16: {=_xlfn.IFS(M7="Low Resistance",0,M7="Medium Resistance",0,M7="High Resistance",1)} -> 0 | D16: {=_xlfn.IFS(N7="1 week",0,N7="1.2 weeks",1,N7="1.5 weeks",0)} -> 0 | E16: {=_xlfn.IFS(N7="1 week",0,N7="1.2 weeks",0,N7="1.5 weeks",1)} -> 1 | F16: {=_xlfn.IFS(O7="No Imperfections",0,O7="Minimal Imperfections",1)} -> 1 | G16: {=_xlfn.IFS(P7=8,0,P7=9,1,P7=10,0)} -> 0 | H16: {=_xlfn.IFS(P7=8,0,P7=9,0,P7=10,1)} -> 0
A17: Bundle 4 | B17: {=_xlfn.IFS(M8="Low Resistance",0,M8="Medium Resistance",1,M8="High Resistance",0)} -> 1 | C17: {=_xlfn.IFS(M8="Low Resistance",0,M8="Medium Resistance",0,M8="High Resistance",1)} -> 0 | D17: {=_xlfn.IFS(N8="1 week",0,N8="1.2 weeks",1,N8="1.5 weeks",0)} -> 0 | E17: {=_xlfn.IFS(N8="1 week",0,N8="1.2 weeks",0,N8="1.5 weeks",1)} -> 0 | F17: {=_xlfn.IFS(O8="No Imperfections",0,O8="Minimal Imperfections",1)} -> 1 | G17: {=_xlfn.IFS(P8=8,0,P8=9,1,P8=10,0)} -> 1 | H17: {=_xlfn.IFS(P8=8,0,P8=9,0,P8=10,1)} -> 0
A18: Bundle 5 | B18: {=_xlfn.IFS(M9="Low Resistance",0,M9="Medium Resistance",1,M9="High Resistance",0)} -> 1 | C18: {=_xlfn.IFS(M9="Low Resistance",0,M9="Medium Resistance",0,M9="High Resistance",1)} -> 0 | D18: {=_xlfn.IFS(N9="1 week",0,N9="1.2 weeks",1,N9="1.5 weeks",0)} -> 1 | E18: {=_xlfn.IFS(N9="1 week",0,N9="1.2 weeks",0,N9="1.5 weeks",1)} -> 0 | F18: {=_xlfn.IFS(O9="No Imperfections",0,O9="Minimal Imperfections",1)} -> 0 | G18: {=_xlfn.IFS(P9=8,0,P9=9,1,P9=10,0)} -> 0 | H18: {=_xlfn.IFS(P9=8,0,P9=9,0,P9=10,1)} -> 0
A19: Bundle 6 | B19: {=_xlfn.IFS(M10="Low Resistance",0,M10="Medium Resistance",1,M10="High Resistance",0)} -> 1 | C19: {=_xlfn.IFS(M10="Low Resistance",0,M10="Medium Resistance",0,M10="High Resistance",1)} -> 0 | D19: {=_xlfn.IFS(N10="1 week",0,N10="1.2 weeks",1,N10="1.5 weeks",0)} -> 0 | E19: {=_xlfn.IFS(N10="1 week",0,N10="1.2 weeks",0,N10="1.5 weeks",1)} -> 1 | F19: {=_xlfn.IFS(O10="No Imperfections",0,O10="Minimal Imperfections",1)} -> 0 | G19: {=_xlfn.IFS(P10=8,0,P10=9,1,P10=10,0)} -> 0 | H19: {=_xlfn.IFS(P10=8,0,P10=9,0,P10=10,1)} -> 1
A20: Bundle 7 | B20: {=_xlfn.IFS(M11="Low Resistance",0,M11="Medium Resistance",1,M11="High Resistance",0)} -> 0 | C20: {=_xlfn.IFS(M11="Low Resistance",0,M11="Medium Resistance",0,M11="High Resistance",1)} -> 1 | D20: {=_xlfn.IFS(N11="1 week",0,N11="1.2 weeks",1,N11="1.5 weeks",0)} -> 0 | E20: {=_xlfn.IFS(N11="1 week",0,N11="1.2 weeks",0,N11="1.5 weeks",1)} -> 0 | F20: {=_xlfn.IFS(O11="No Imperfections",0,O11="Minimal Imperfections",1)} -> 0 | G20: {=_xlfn.IFS(P11=8,0,P11=9,1,P11=10,0)} -> 0 | H20: {=_xlfn.IFS(P11=8,0,P11=9,0,P11=10,1)} -> 0
A21: Bundle 8 | B21: {=_xlfn.IFS(M12="Low Resistance",0,M12="Medium Resistance",1,M12="High Resistance",0)} -> 0 | C21: {=_xlfn.IFS(M12="Low Resistance",0,M12="Medium Resistance",0,M12="High Resistance",1)} -> 1 | D21: {=_xlfn.IFS(N12="1 week",0,N12="1.2 weeks",1,N12="1.5 weeks",0)} -> 1 | E21: {=_xlfn.IFS(N12="1 week",0,N12="1.2 weeks",0,N12="1.5 weeks",1)} -> 0 | F21: {=_xlfn.IFS(O12="No Imperfections",0,O12="Minimal Imperfections",1)} -> 1 | G21: {=_xlfn.IFS(P12=8,0,P12=9,1,P12=10,0)} -> 0 | H21: {=_xlfn.IFS(P12=8,0,P12=9,0,P12=10,1)} -> 1
A22: Bundle 9 | B22: {=_xlfn.IFS(M13="Low Resistance",0,M13="Medium Resistance",1,M13="High Resistance",0)} -> 0 | C22: {=_xlfn.IFS(M13="Low Resistance",0,M13="Medium Resistance",0,M13="High Resistance",1)} -> 1 | D22: {=_xlfn.IFS(N13="1 week",0,N13="1.2 weeks",1,N13="1.5 weeks",0)} -> 0 | E22: {=_xlfn.IFS(N13="1 week",0,N13="1.2 weeks",0,N13="1.5 weeks",1)} -> 1 | F22: {=_xlfn.IFS(O13="No Imperfections",0,O13="Minimal Imperfections",1)} -> 0 | G22: {=_xlfn.IFS(P13=8,0,P13=9,1,P13=10,0)} -> 1 | H22: {=_xlfn.IFS(P13=8,0,P13=9,0,P13=10,1)} -> 0
A25: Respondents' Ratings
A26: Bundle | B26: Respondent
B27: Respondent 1 | C27: Respondent 2 | D27: Respondent 3 | E27: Respondent 4 | F27: Respondent 5 | G27: Respondent 6 | H27: Respondent 7 | I27: Respondent 8 | J27: Respondent 9 | K27: Respondent 10 | L27: Respondent 11 | M27: Respondent 12 | N27: Respondent 13 | O27: Respondent 14 | P27: Respondent 15 | Q27: Respondent 16 | R27: Respondent 17 | S27: Respondent 18 | T27: Respondent 19 | U27: Respondent 20
A28: Bundle 1 | B28: 79 | C28: 96 | D28: 50 | E28: 49 | F28: 65 | G28: 86 | H28: 49 | I28: 83 | J28: 49 | K28: 67 | L28: 38 | M28: 57 | N28: 79 | O28: 96 | P28: 53 | Q28: 64 | R28: 60 | S28: 90 | T28: 69 | U28: 93
A29: Bundle 2 | B29: 60 | C29: 81 | D29: 44 | E29: 45 | F29: 57 | G29: 62 | H29: 34 | I29: 90 | J29: 30 | K29: 52 | L29: 30 | M29: 47 | N29: 77 | O29: 98 | P29: 47 | Q29: 61 | R29: 59 | S29: 89 | T29: 67 | U29: 52
A30: Bundle 3 | B30: 42 | C30: 73 | D30: 41 | E30: 37 | F30: 63 | G30: 58 | H30: 22 | I30: 77 | J30: 23 | K30: 51 | L30: 41 | M30: 49 | N30: 88 | O30: 48 | P30: 47 | Q30: 58 | R30: 49 | S30: 87 | T30: 47 | U30: 46
A31: Bundle 4 | B31: 58 | C31: 50 | D31: 31 | E31: 49 | F31: 53 | G31: 74 | H31: 41 | I31: 60 | J31: 33 | K31: 66 | L31: 40 | M31: 50 | N31: 47 | O31: 74 | P31: 39 | Q31: 38 | R31: 54 | S31: 82 | T31: 50 | U31: 59
A32: Bundle 5 | B32: 50 | C32: 51 | D32: 38 | E32: 44 | F32: 50 | G32: 60 | H32: 32 | I32: 65 | J32: 30 | K32: 43 | L32: 22 | M32: 56 | N32: 68 | O32: 98 | P32: 29 | Q32: 48 | R32: 53 | S32: 86 | T32: 48 | U32: 30
A33: Bundle 6 | B33: 41 | C33: 29 | D33: 23 | E33: 29 | F33: 39 | G33: 51 | H33: 20 | I33: 50 | J33: 22 | K33: 15 | L33: 19 | M33: 28 | N33: 40 | O33: 55 | P33: 21 | Q33: 27 | R33: 36 | S33: 68 | T33: 29 | U33: 18
A34: Bundle 7 | B34: 71 | C34: 67 | D34: 38 | E34: 50 | F34: 47 | G34: 67 | H34: 46 | I34: 66 | J34: 48 | K34: 72 | L34: 27 | M34: 58 | N34: 71 | O34: 93 | P34: 36 | Q34: 48 | R34: 55 | S34: 89 | T34: 46 | U34: 77
A35: Bundle 8 | B35: 33 | C35: 26 | D35: 16 | E35: 33 | F35: 22 | G35: 31 | H35: 25 | I35: 35 | J35: 12 | K35: 19 | L35: 25 | M35: 18 | N35: 40 | O35: 65 | P35: 18 | Q35: 28 | R35: 41 | S35: 65 | T35: 32 | U35: 6
A36: Bundle 9 | B36: 30 | C36: 20 | D36: 11 | E36: 30 | F36: 26 | G36: 28 | H36: 15 | I36: 46 | J36: 11 | K36: 29 | L36: 21 | M36: 14 | N36: 37 | O36: 34 | P36: 22 | Q36: 22 | R36: 35 | S36: 66 | T36: 16 | U36: 12
A39: Part-worth Estimation
A40: Variables | B40: Respondent
B41: Respondent 1 | C41: Respondent 2 | D41: Respondent 3 | E41: Respondent 4 | F41: Respondent 5 | G41: Respondent 6 | H41: Respondent 7 | I41: Respondent 8 | J41: Respondent 9 | K41: Respondent 10 | L41: Respondent 11 | M41: Respondent 12 | N41: Respondent 13 | O41: Respondent 14 | P41: Respondent 15 | Q41: Respondent 16 | R41: Respondent 17 | S41: Respondent 18 | T41: Respondent 19 | U41: Respondent 20
A42: Resist_Med | B42: ='Respondent 1-5 regression'!B19 -> -10.666667 | C42: ='Respondent 1-5 regression'!B45 -> -40 | D42: ='Respondent 1-5 regression'!B71 -> -14.333333 | E42: ='Respondent 1-5 regression'!B97 -> -3 | F42: ='Respondent 1-5 regression'!B123 -> -14.333333 | G42: ='Respondent 6-10 regression'!B19 -> -7 | H42: ='Respondent 6-10 regression'!B45 -> -4 | I42: ='Respondent 6-10 regression'!B71 -> -25 | J42: ='Respondent 6-10 regression'!B97 -> -5.6666667 | K42: ='Respondent 6-10 regression'!B123 -> -15.333333 | L42: ='Respondent 11-15 regression'!B19 -> -9.3333333 | M42: ='Respondent 11-15 regression'!B45 -> -6.3333333 | N42: ='Respondent 11-15 regression'!B71 -> -29.666667 | O42: ='Respondent 11-15 regression'!B97 -> -5 | P42: ='Respondent 11-15 regression'!B123 -> -19.333333 | Q42: ='Respondent 16-20 regressions'!B19 -> -23.333333 | R42: ='Respondent 16-20 regressions'!B45 -> -8.3333333 | S42: ='Respondent 16-20 regressions'!B71 -> -10 | T42: ='Respondent 16-20 regressions'!B97 -> -18.666667 | U42: ='Respondent 16-20 regressions'!B123 -> -28
A43: Resist_High | B43: ='Respondent 1-5 regression'!B20 -> -15.666667 | C43: ='Respondent 1-5 regression'!B46 -> -45.666667 | D43: ='Respondent 1-5 regression'!B72 -> -23.333333 | E43: ='Respondent 1-5 regression'!B98 -> -6 | F43: ='Respondent 1-5 regression'!B124 -> -30 | G43: ='Respondent 6-10 regression'!B20 -> -26.666667 | H43: ='Respondent 6-10 regression'!B46 -> -6.3333333 | I43: ='Respondent 6-10 regression'!B72 -> -34.333333 | J43: ='Respondent 6-10 regression'!B98 -> -10.333333 | K43: ='Respondent 6-10 regression'!B124 -> -16.666667 | L43: ='Respondent 11-15 regression'!B20 -> -12 | M43: ='Respondent 11-15 regression'!B46 -> -21 | N43: ='Respondent 11-15 regression'!B72 -> -32 | O43: ='Respondent 11-15 regression'!B98 -> -16.666667 | P43: ='Respondent 11-15 regression'!B124 -> -23.666667 | Q43: ='Respondent 16-20 regressions'!B20 -> -28.333333 | R43: ='Respondent 16-20 regressions'!B46 -> -12.333333 | S43: ='Respondent 16-20 regressions'!B72 -> -15.333333 | T43: ='Respondent 16-20 regressions'!B98 -> -29.666667 | U43: ='Respondent 16-20 regressions'!B124 -> -32
A44: Speed_1.2 | B44: ='Respondent 1-5 regression'!B21 -> -21.666667 | C44: ='Respondent 1-5 regression'!B47 -> -18.333333 | D44: ='Respondent 1-5 regression'!B73 -> -7 | E44: ='Respondent 1-5 regression'!B99 -> -8.6666667 | F44: ='Respondent 1-5 regression'!B125 -> -12 | G44: ='Respondent 6-10 regression'!B21 -> -24.666667 | H44: ='Respondent 6-10 regression'!B47 -> -15 | I44: ='Respondent 6-10 regression'!B73 -> -6.3333333 | J44: ='Respondent 6-10 regression'!B99 -> -19.333333 | K44: ='Respondent 6-10 regression'!B125 -> -30.333333 | L44: ='Respondent 11-15 regression'!B21 -> -9.3333333 | M44: ='Respondent 11-15 regression'!B47 -> -14.666667 | N44: ='Respondent 11-15 regression'!B73 -> -4 | O44: ='Respondent 11-15 regression'!B99 -> -0.66666667 | P44: ='Respondent 11-15 regression'!B125 -> -11.333333 | Q44: ='Respondent 16-20 regressions'!B21 -> -4.3333333 | R44: ='Respondent 16-20 regressions'!B47 -> -5.3333333 | S44: ='Respondent 16-20 regressions'!B73 -> -7 | T44: ='Respondent 16-20 regressions'!B99 -> -6 | U44: ='Respondent 16-20 regressions'!B125 -> -47
A45: Speed_1.5 | B45: ='Respondent 1-5 regression'!B22 -> -31.666667 | C45: ='Respondent 1-5 regression'!B48 -> -30.333333 | D45: ='Respondent 1-5 regression'!B74 -> -14.666667 | E45: ='Respondent 1-5 regression'!B100 -> -17.333333 | F45: ='Respondent 1-5 regression'!B126 -> -12.333333 | G45: ='Respondent 6-10 regression'!B22 -> -30 | H45: ='Respondent 6-10 regression'!B48 -> -26.333333 | I45: ='Respondent 6-10 regression'!B74 -> -12 | J45: ='Respondent 6-10 regression'!B100 -> -24.666667 | K45: ='Respondent 6-10 regression'!B126 -> -36.666667 | L45: ='Respondent 11-15 regression'!B22 -> -8 | M45: ='Respondent 11-15 regression'!B48 -> -24.666667 | N45: ='Respondent 11-15 regression'!B74 -> -10.666667 | O45: ='Respondent 11-15 regression'!B100 -> -42 | P45: ='Respondent 11-15 regression'!B126 -> -12.666667 | Q45: ='Respondent 16-20 regressions'!B22 -> -14.333333 | R45: ='Respondent 16-20 regressions'!B48 -> -16.333333 | S45: ='Respondent 16-20 regressions'!B74 -> -13.333333 | T45: ='Respondent 16-20 regressions'!B100 -> -24.333333 | U45: ='Respondent 16-20 regressions'!B126 -> -51
...

Sheet Key Results Summary
A1: KEY RESULTS SUMMARY — Homer & Co. Conjoint Analysis
A3: Overall Attribute Importance (average %)
A4: Attribute | B4: Importance (%)
A5: Life Expectancy | B5: ='Data and Analysis'!V64 -> 0.35906103
A6: Speed of Installation | B6: ='Data and Analysis'!V65 -> 0.37674921
A7: Shingle Aesthetics | B7: ='Data and Analysis'!V66 -> 0.089393068
A8: Price | B8: ='Data and Analysis'!V67 -> 0.17479669
A11: Attribute Importance by Segment (average %)
A12: Attribute | B12: Segment 1 | C12: Segment 2 | D12: Segment 3
A13: Life Expectancy | B13: ='Data and Analysis'!B79 -> 0.24835226 | C13: ='Data and Analysis'!C79 -> 0.49338758 | D13: ='Data and Analysis'!D79 -> 0.33298323
A14: Speed of Installation | B14: ='Data and Analysis'!B80 -> 0.50240077 | C14: ='Data and Analysis'!C80 -> 0.26076164 | D14: ='Data and Analysis'!D80 -> 0.30909474
A15: Shingle Aesthetics | B15: ='Data and Analysis'!B81 -> 0.098718222 | C15: ='Data and Analysis'!C81 -> 0.061223335 | D15: ='Data and Analysis'!D81 -> 0.13653689
A16: Price | B16: ='Data and Analysis'!B82 -> 0.15052875 | C16: ='Data and Analysis'!C82 -> 0.18462745 | D16: ='Data and Analysis'!D82 -> 0.22138514
A17: Number of Customers (n) | B17: ='Data and Analysis'!B84 -> 9 | C17: ='Data and Analysis'!C84 -> 8 | D17: ='Data and Analysis'!D84 -> 3
A20: Overall Utilities of Current Choice (average)
A21: Attribute | B21: Value
A22: Bundle 1 | B22: ='Data and Analysis'!V90 -> -9.9666667
A23: Bundle 2 | B23: ='Data and Analysis'!V91 -> -21.4
A24: Bundle 3 | B24: ='Data and Analysis'!V92 -> -27.183333
A25: Bundle 4 | B25: ='Data and Analysis'!V93 -> -27.133333
A26: Bundle 5 | B26: ='Data and Analysis'!V94 -> -28.516667
A27: Bundle 6 | B27: ='Data and Analysis'!V95 -> -47.5
A28: Bundle 7 | B28: ='Data and Analysis'!V96 -> -21.9
A29: Bundle 8 | B29: ='Data and Analysis'!V97 -> -50.033333
A30: Bundle 9 | B30: ='Data and Analysis'!V98 -> -52.316667
A33: Overall Purchase Probability Compared to the Competitors (average %)
A34: Attribute | B34: Value
A35: Bundle 1 | B35: ='Data and Analysis'!V122 -> 0.89130507
A36: Bundle 2 | B36: ='Data and Analysis'!V123 -> 0.50414376
A37: Bundle 3 | B37: ='Data and Analysis'!V124 -> 0.23766366
A38: Bundle 4 | B38: ='Data and Analysis'!V125 -> 0.26092593
A39: Bundle 5 | B39: ='Data and Analysis'!V126 -> 0.27058202
A40: Bundle 6 | B40: ='Data and Analysis'!V127 -> 1.4703324e-06
A41: Bundle 7 | B41: ='Data and Analysis'!V128 -> 0.53001387
A42: Bundle 8 | B42: ='Data and Analysis'!V129 -> 2.2522019e-06
A43: Bundle 9 | B43: ='Data and Analysis'!V130 -> 7.39639e-08
A46: Purchase Probability Compared to the Competitors by segment (average %)
A47: Attribute | B47: Segment 1 | C47: Segment 2 | D47: Segment 3
A48: Bundle 1 | B48: =AVERAGEIF('Data and Analysis'!$B$73:$U$73,1,'Data and Analysis'!B122:U122) -> 0.99933646 | C48: =AVERAGEIF('Data and Analysis'!$B$73:$U$73,2,'Data and Analysis'!B122:U122) -> 0.8551917 | D48: =AVERAGEIF('Data and Analysis'!$B$73:$U$73,3,'Data and Analysis'!B122:U122) -> 0.66351322
A49: Bundle 2 | B49: =AVERAGEIF('Data and Analysis'!$B$73:$U$73,1,'Data and Analysis'!B123:U123) -> 0.4491002 | C49: =AVERAGEIF('Data and Analysis'!$B$73:$U$73,2,'Data and Analysis'!B123:U123) -> 0.65670028 | D49: =AVERAGEIF('Data and Analysis'!$B$73:$U$73,3,'Data and Analysis'!B123:U123) -> 0.26245707
...

Sheet Respondent 1-5 regression
A1: RESPONDENT 1
A2: SUMMARY OUTPUT
A4: Regression Statistics
A5: Multiple R | B5: 0.99374396
A6: R Square | B6: 0.98752706
A7: Adjusted R Square | B7: 0.90021649
A8: Standard Error | B8: 5.3072278
A9: Observations | B9: 9
A11: ANOVA
B12: df | C12: SS | D12: MS | E12: F | F12: Significance F
A13: Regression | B13: 7 | C13: 2230.0556 | D13: 318.57937 | E13: 11.31051 | F13: 0.22516575
A14: Residual | B14: 1 | C14: 28.166667 | D14: 28.166667
A15: Total | B15: 8 | C15: 2258.2222
B17: Coefficients | C17: Standard Error | D17: t Stat | E17: P-value | F17: Lower 95% | G17: Upper 95%
A18: Intercept | B18: 84.5 | C18: 4.844814 | D18: 17.44133 | E18: 0.036460726 | F18: 22.940802 | G18: 146.0592
A19: Resist_Med | B19: -10.666667 | C19: 4.3333333 | D19: -2.4615385 | E19: 0.24566054 | F19: -65.726887 | G19: 44.393554
A20: Resist_High | B20: -15.666667 | C20: 4.3333333 | D20: -3.6153846 | E20: 0.17179131 | F20: -70.726887 | G20: 39.393554
A21: Speed_1.2 | B21: -21.666667 | C21: 4.3333333 | D21: -5 | E21: 0.12566592 | F21: -76.726887 | G21: 33.393554
A22: Speed_1.5 | B22: -31.666667 | C22: 4.3333333 | D22: -7.3076923 | E22: 0.086578645 | F22: -86.726887 | G22: 23.393554
A23: Shingle_Minimal | B23: -10.833333 | C23: 3.7527767 | D23: -2.8867513 | E23: 0.21229562 | F23: -58.516883 | G23: 36.850216
A24: Price_9 | B24: -5 | C24: 4.3333333 | D24: -1.1538462 | E24: 0.45460426 | F24: -60.060221 | G24: 50.060221
A25: Price_10 | B25: -3.3333333 | C25: 4.3333333 | D25: -0.76923077 | E25: 0.5825712 | F25: -58.393554 | G25: 51.726887
A27: RESPONDENT 2
A28: SUMMARY OUTPUT
A30: Regression Statistics
A31: Multiple R | B31: 0.9985128
A32: R Square | B32: 0.99702782
A33: Adjusted R Square | B33: 0.97622256
A34: Standard Error | B34: 4.0824829
A35: Observations | B35: 9
A37: ANOVA
B38: df | C38: SS | D38: MS | E38: F | F38: Significance F
A39: Regression | B39: 7 | C39: 5590.8889 | D39: 798.69841 | E39: 47.921905 | F39: 0.11078785
A40: Residual | B40: 1 | C40: 16.666667 | D40: 16.666667
A41: Total | B41: 8 | C41: 5607.5556
B43: Coefficients | C43: Standard Error | D43: t Stat | E43: P-value | F43: Lower 95% | G43: Upper 95% | H43: Lower 95.0% | I43: Upper 95.0%
A44: Intercept | B44: 111 | C44: 3.72678 | D44: 29.784425 | E44: 0.021366225 | F44: 63.646771 | G44: 158.35323 | H44: 63.646771 | I44: 158.35323
A45: Resist_Med | B45: -40 | C45: 3.3333333 | D45: -12 | E45: 0.052929352 | F45: -82.354016 | G45: 2.3540158 | H45: -82.354016 | I45: 2.3540158
A46: Resist_High | B46: -45.666667 | C46: 3.3333333 | D46: -13.7 | E46: 0.046386332 | F46: -88.020682 | G46: -3.3126509 | H46: -88.020682 | I46: -3.3126509
A47: Speed_1.2 | B47: -18.333333 | C47: 3.3333333 | D47: -5.5 | E47: 0.11449829 | F47: -60.687349 | G47: 24.020682 | H47: -60.687349 | I47: 24.020682
...

Sheet Respondent 6-10 regression
A1: RESPONDENT 6
A2: SUMMARY OUTPUT
A4: Regression Statistics
A5: Multiple R | B5: 0.99893418
A6: R Square | B6: 0.99786949
A7: Adjusted R Square | B7: 0.98295589
A8: Standard Error | B8: 2.4494897
A9: Observations | B9: 9
A11: ANOVA
B12: df | C12: SS | D12: MS | E12: F | F12: Significance F
A13: Regression | B13: 7 | C13: 2810.2222 | D13: 401.46032 | E13: 66.910053 | F13: 0.093864477
A14: Residual | B14: 1 | C14: 6 | D14: 6
A15: Total | B15: 8 | C15: 2816.2222
B17: Coefficients | C17: Standard Error | D17: t Stat | E17: P-value | F17: Lower 95% | G17: Upper 95% | H17: Lower 95.0% | I17: Upper 95.0%
A18: Intercept | B18: 92.666667 | C18: 2.236068 | D18: 41.441793 | E18: 0.015358801 | F18: 64.254729 | G18: 121.0786 | H18: 64.254729 | I18: 121.0786
A19: Resist_Med | B19: -7 | C19: 2 | D19: -3.5 | E19: 0.17717107 | F19: -32.412409 | G19: 18.412409 | H19: -32.412409 | I19: 18.412409
A20: Resist_High | B20: -26.666667 | C20: 2 | D20: -13.333333 | E20: 0.047657259 | F20: -52.079076 | G20: -1.2542572 | H20: -52.079076 | I20: -1.2542572
A21: Speed_1.2 | B21: -24.666667 | C21: 2 | D21: -12.333333 | E21: 0.051505149 | F21: -50.079076 | G21: 0.74574281 | H21: -50.079076 | I21: 0.74574281
A22: Speed_1.5 | B22: -30 | C22: 2 | D22: -15 | E22: 0.042378609 | F22: -55.412409 | G22: -4.5875905 | H22: -55.412409 | I22: -4.5875905
A23: Shingle_Minimal | B23: -4.6666667 | C23: 1.7320508 | D23: -2.6943013 | E23: 0.22625107 | F23: -26.674459 | G23: 17.341126 | H23: -26.674459 | I23: 17.341126
A24: Price_9 | B24: -7 | C24: 2 | D24: -3.5 | E24: 0.17717107 | F24: -32.412409 | G24: 18.412409 | H24: -32.412409 | I24: 18.412409
A25: Price_10 | B25: -5.6666667 | C25: 2 | D25: -2.8333333 | E25: 0.21600039 | F25: -31.079076 | G25: 19.745743 | H25: -31.079076 | I25: 19.745743
A27: RESPONDENT 7
A28: SUMMARY OUTPUT
A30: Regression Statistics
A31: Multiple R | B31: 0.99884013
A32: R Square | B32: 0.99768161
A33: Adjusted R Square | B33: 0.98145286
A34: Standard Error | B34: 1.6329932
A35: Observations | B35: 9
A37: ANOVA
B38: df | C38: SS | D38: MS | E38: F | F38: Significance F
A39: Regression | B39: 7 | C39: 1147.5556 | D39: 163.93651 | E39: 61.47619 | F39: 0.09790043
A40: Residual | B40: 1 | C40: 2.6666667 | D40: 2.6666667
A41: Total | B41: 8 | C41: 1150.2222
B43: Coefficients | C43: Standard Error | D43: t Stat | E43: P-value | F43: Lower 95% | G43: Upper 95% | H43: Lower 95.0% | I43: Upper 95.0%
A44: Intercept | B44: 51.666667 | C44: 1.490712 | D44: 34.659054 | E44: 0.018362971 | F44: 32.725375 | G44: 70.607958 | H44: 32.725375 | I44: 70.607958
A45: Resist_Med | B45: -4 | C45: 1.3333333 | D45: -3 | E45: 0.20483276 | F45: -20.941606 | G45: 12.941606 | H45: -20.941606 | I45: 12.941606
A46: Resist_High | B46: -6.3333333 | C46: 1.3333333 | D46: -4.75 | E46: 0.1320962 | F46: -23.27494 | G46: 10.608273 | H46: -23.27494 | I46: 10.608273
A47: Speed_1.2 | B47: -15 | C47: 1.3333333 | D47: -11.25 | E47: 0.056440087 | F47: -31.941606 | G47: 1.9416063 | H47: -31.941606 | I47: 1.9416063
...

Sheet Respondent 11-15 regression
A1: RESPONDENT 11
A2: SUMMARY OUTPUT
A4: Regression Statistics
A5: Multiple R | B5: 0.99639881
A6: R Square | B6: 0.99281058
A7: Adjusted R Square | B7: 0.94248466
A8: Standard Error | B8: 2.0412415
A9: Observations | B9: 9
A11: ANOVA
B12: df | C12: SS | D12: MS | E12: F | F12: Significance F
A13: Regression | B13: 7 | C13: 575.38889 | D13: 82.198413 | E13: 19.727619 | F13: 0.17170211
A14: Residual | B14: 1 | C14: 4.1666667 | D14: 4.1666667
A15: Total | B15: 8 | C15: 579.55556
B17: Coefficients | C17: Standard Error | D17: t Stat | E17: P-value | F17: Lower 95% | G17: Upper 95% | H17: Lower 95.0% | I17: Upper 95.0%
A18: Intercept | B18: 39.833333 | C18: 1.86339 | D18: 21.37681 | E18: 0.029759165 | F18: 16.156719 | G18: 63.509948 | H18: 16.156719 | I18: 63.509948
A19: Resist_Med | B19: -9.3333333 | C19: 1.6666667 | D19: -5.6 | E19: 0.11249635 | F19: -30.510341 | G19: 11.843675 | H19: -30.510341 | I19: 11.843675
A20: Resist_High | B20: -12 | C20: 1.6666667 | D20: -7.2 | E20: 0.087857363 | F20: -33.177008 | G20: 9.1770079 | H20: -33.177008 | I20: 9.1770079
A21: Speed_1.2 | B21: -9.3333333 | C21: 1.6666667 | D21: -5.6 | E21: 0.11249635 | F21: -30.510341 | G21: 11.843675 | H21: -30.510341 | I21: 11.843675
A22: Speed_1.5 | B22: -8 | C22: 1.6666667 | D22: -4.8 | E22: 0.13075877 | F22: -29.177008 | G22: 13.177008 | H22: -29.177008 | I22: 13.177008
A23: Shingle_Minimal | B23: 9.1666667 | C23: 1.4433757 | D23: 6.350853 | E23: 0.099425284 | F23: -9.1731601 | G23: 27.506493 | H23: -9.1731601 | I23: 27.506493
A24: Price_9 | B24: 0.33333333 | C24: 1.6666667 | D24: 0.2 | E24: 0.87433408 | F24: -20.843675 | G24: 21.510341 | H24: -20.843675 | I24: 21.510341
A25: Price_10 | B25: -2.6666667 | C25: 1.6666667 | D25: -1.6 | E25: 0.35561537 | F25: -23.843675 | G25: 18.510341 | H25: -23.843675 | I25: 18.510341
A27: RESPONDENT 12
A28: SUMMARY OUTPUT
A30: Regression Statistics
A31: Multiple R | B31: 0.99873385
A32: R Square | B32: 0.9974693
A33: Adjusted R Square | B33: 0.97975443
A34: Standard Error | B34: 2.4494897
A35: Observations | B35: 9
A37: ANOVA
B38: df | C38: SS | D38: MS | E38: F | F38: Significance F
A39: Regression | B39: 7 | C39: 2364.8889 | D39: 337.84127 | E39: 56.306878 | F39: 0.10226672
A40: Residual | B40: 1 | C40: 6 | D40: 6
A41: Total | B41: 8 | C41: 2370.8889
B43: Coefficients | C43: Standard Error | D43: t Stat | E43: P-value | F43: Lower 95% | G43: Upper 95% | H43: Lower 95.0% | I43: Upper 95.0%
A44: Intercept | B44: 78 | C44: 2.236068 | D44: 34.88266 | E44: 0.018245325 | F44: 49.588062 | G44: 106.41194 | H44: 49.588062 | I44: 106.41194
A45: Resist_Med | B45: -6.3333333 | C45: 2 | D45: -3.1666667 | E45: 0.19472854 | F45: -31.745743 | G45: 19.079076 | H45: -31.745743 | I45: 19.079076
A46: Resist_High | B46: -21 | C46: 2 | D46: -10.5 | E46: 0.060448134 | F46: -46.412409 | G46: 4.4124095 | H46: -46.412409 | I46: 4.4124095
A47: Speed_1.2 | B47: -14.666667 | C47: 2 | D47: -7.3333333 | E47: 0.086279622 | F47: -40.079076 | G47: 10.745743 | H47: -40.079076 | I47: 10.745743
...

Sheet Respondent 16-20 regressions
A1: RESPONDENT 16
A2: SUMMARY OUTPUT
A4: Regression Statistics
A5: Multiple R | B5: 0.99983177
A6: R Square | B6: 0.99966356
A7: Adjusted R Square | B7: 0.99730851
A8: Standard Error | B8: 0.81649658
A9: Observations | B9: 9
A11: ANOVA
B12: df | C12: SS | D12: MS | E12: F | F12: Significance F
A13: Regression | B13: 7 | C13: 1980.8889 | D13: 282.98413 | E13: 424.47619 | F13: 0.037355933
A14: Residual | B14: 1 | C14: 0.66666667 | D14: 0.66666667
A15: Total | B15: 8 | C15: 1981.5556
B17: Coefficients | C17: Standard Error | D17: t Stat | E17: P-value | F17: Lower 95% | G17: Upper 95% | H17: Lower 95.0% | I17: Upper 95.0%
A18: Intercept | B18: 76 | C18: 0.74535599 | D18: 101.9647 | E18: 0.0062433309 | F18: 66.529354 | G18: 85.470646 | H18: 66.529354 | I18: 85.470646
A19: Resist_Med | B19: -23.333333 | C19: 0.66666667 | D19: -35 | E19: 0.018184189 | F19: -31.804136 | G19: -14.86253 | H19: -31.804136 | I19: -14.86253
A20: Resist_High | B20: -28.333333 | C20: 0.66666667 | D20: -42.5 | E20: 0.014976525 | F20: -36.804136 | G20: -19.86253 | H20: -36.804136 | I20: -19.86253
A21: Speed_1.2 | B21: -4.3333333 | C21: 0.66666667 | D21: -6.5 | E21: 0.097179581 | F21: -12.804136 | G21: 4.1374698 | H21: -12.804136 | I21: 4.1374698
A22: Speed_1.5 | B22: -14.333333 | C22: 0.66666667 | D22: -21.5 | E22: 0.029588897 | F22: -22.804136 | G22: -5.8625302 | H22: -22.804136 | I22: -5.8625302
A23: Shingle_Minimal | B23: -3.6666667 | C23: 0.57735027 | D23: -6.350853 | E23: 0.099425284 | F23: -11.002597 | G23: 3.6692641 | H23: -11.002597 | I23: 3.6692641
A24: Price_9 | B24: -11 | C24: 0.66666667 | D24: -16.5 | E24: 0.038535881 | F24: -19.470803 | G24: -2.5291968 | H24: -19.470803 | I24: -2.5291968
A25: Price_10 | B25: -11.666667 | C25: 0.66666667 | D25: -17.5 | E25: 0.036338755 | F25: -20.13747 | G25: -3.1958635 | H25: -20.13747 | I25: -3.1958635
A27: RESPONDENT 17
A28: SUMMARY OUTPUT
A30: Regression Statistics
A31: Multiple R | B31: 0.99954132
A32: R Square | B32: 0.99908285
A33: Adjusted R Square | B33: 0.99266279
A34: Standard Error | B34: 0.81649658
A35: Observations | B35: 9
A37: ANOVA
B38: df | C38: SS | D38: MS | E38: F | F38: Significance F
A39: Regression | B39: 7 | C39: 726.22222 | D39: 103.74603 | E39: 155.61905 | F39: 0.061647936
A40: Residual | B40: 1 | C40: 0.66666667 | D40: 0.66666667
A41: Total | B41: 8 | C41: 726.88889
B43: Coefficients | C43: Standard Error | D43: t Stat | E43: P-value | F43: Lower 95% | G43: Upper 95% | H43: Lower 95.0% | I43: Upper 95.0%
A44: Intercept | B44: 67 | C44: 0.74535599 | D44: 89.889933 | E44: 0.0070819222 | F44: 57.529354 | G44: 76.470646 | H44: 57.529354 | I44: 76.470646
A45: Resist_Med | B45: -8.3333333 | C45: 0.66666667 | D45: -12.5 | E45: 0.050821347 | F45: -16.804136 | G45: 0.13746982 | H45: -16.804136 | I45: 0.13746982
A46: Resist_High | B46: -12.333333 | C46: 0.66666667 | D46: -18.5 | E46: 0.034378423 | F46: -20.804136 | G46: -3.8625302 | H46: -20.804136 | I46: -3.8625302
A47: Speed_1.2 | B47: -5.3333333 | C47: 0.66666667 | D47: -8 | E47: 0.079166848 | F47: -13.804136 | G47: 3.1374698 | H47: -13.804136 | I47: 3.1374698
...
